<?xml version="1.0" ?>
<!-- =================================================================================== -->
<!-- |    This document was autogenerated by xacro from Toshiba_Robot_R02.urdf.xacro   | -->
<!-- |    EDITING THIS FILE BY HAND IS NOT RECOMMENDED                                 | -->
<!-- =================================================================================== -->
<robot name="sr_scara_hx" xmlns:xacro="http://www.ros.org/wiki/xacro">
  <!-- Include materials -->
  <material name="Black">
    <color rgba="0.0 0.0 0.0 1.0"/>
  </material>
  <material name="Red">
    <color rgba="0.8 0.0 0.0 1.0"/>
  </material>
  <material name="White">
    <color rgba="1.0 1.0 1.0 1.0"/>
  </material>
  <!--Links -->
  <!--<xacro:property name="xyz1" value="0 0 0.097"/> -->
  <!--<xacro:property name="rpy1" value="0 0 0" /> -->
  <link name="base_link">
    <visual>
      <origin rpy="0 0 0" xyz="0 0 0.097"/>
      <geometry>
        <mesh filename="package://robot_simulation/meshes_r01/base.stl" scale="0.001 0.001 0.001"/>
      </geometry>
      <material name="Black">
        <color rgba="0.1 0.1 0.1 1"/>
      </material>
    </visual>
    <collision>
      <origin rpy="0 0 0" xyz="0 0 0.097"/>
      <geometry>
        <mesh filename="package://robot_simulation/meshes_r01/base.stl" scale="0.001 0.001 0.001"/>
      </geometry>
    </collision>
    <inertial>
      <mass value="1"/>
      <inertia ixx="1.0" ixy="0.0" ixz="0.0" iyy="0.5" iyz="0.0" izz="1.0"/>
    </inertial>
  </link>
  <gazebo reference="base_link">
    <material>Gazebo/White</material>
  </gazebo>
  <link name="link1">
    <visual>
      <origin rpy="0 0 0" xyz="0 0 0"/>
      <geometry>
        <mesh filename="package://robot_simulation/meshes_r01/link1.stl" scale="0.001 0.001 0.001"/>
      </geometry>
      <material name="Red">
        <color rgba="0.9 0.1 0.1 1"/>
      </material>
    </visual>
    <collision>
      <origin rpy="0 0 0" xyz="0 0 0"/>
      <geometry>
        <mesh filename="package://robot_simulation/meshes_r01/link1.stl" scale="0.001 0.001 0.001"/>
      </geometry>
    </collision>
    <inertial>
      <mass value="1"/>
      <inertia ixx="1.0" ixy="0.0" ixz="0.0" iyy="0.5" iyz="0.0" izz="1.0"/>
    </inertial>
  </link>
  <gazebo reference="link1">
    <material>Gazebo/Red</material>
  </gazebo>
  <link name="link2">
    <visual>
      <origin rpy="0 0 0" xyz="-0.198 0 0"/>
      <geometry>
        <mesh filename="package://robot_simulation/meshes_r01/link2.stl" scale="0.001 0.001 0.001"/>
      </geometry>
      <material name="Black">
        <color rgba="0.1 0.1 0.1 1"/>
      </material>
    </visual>
    <collision>
      <origin rpy="0 0 0" xyz="-0.198 0 0"/>
      <geometry>
        <mesh filename="package://robot_simulation/meshes_r01/link2.stl" scale="0.001 0.001 0.001"/>
      </geometry>
    </collision>
    <inertial>
      <mass value="1"/>
      <inertia ixx="1.0" ixy="0.0" ixz="0.0" iyy="0.5" iyz="0.0" izz="1.0"/>
    </inertial>
  </link>
  <gazebo reference="link2">
    <material>Gazebo/Black</material>
  </gazebo>
  <link name="probe">
    <visual>
      <origin rpy="0 0 0" xyz="-0.344 0 0"/>
      <geometry>
        <mesh filename="package://robot_simulation/meshes_r01/probe.stl" scale="0.001 0.001 0.001"/>
      </geometry>
      <material name="Red">
        <color rgba="0.7 0.1 0.1 1"/>
      </material>
    </visual>
    <collision>
      <origin rpy="0 0 0" xyz="-0.344 0 0"/>
      <geometry>
        <mesh filename="package://robot_simulation/meshes_r01/probe.stl" scale="0.001 0.001 0.001"/>
      </geometry>
    </collision>
    <inertial>
      <mass value="1"/>
      <inertia ixx="1.0" ixy="0.0" ixz="0.0" iyy="0.5" iyz="0.0" izz="1.0"/>
    </inertial>
  </link>
  <gazebo reference="probe">
    <material>Gazebo/Red</material>
  </gazebo>
  <!-- Joints -->
  <!-- BOTTOM FIXED LINK 
This link is the base of the arm in which arm is placed 
-->
  <!-- ///////////////////////////////////////////////////////////////////////////////////////////////////////////////////// -->
  <joint name="bottom_joint" type="fixed">
    <origin rpy="0 0 0" xyz="0 0 0"/>
    <parent link="base_link"/>
    <child link="bottom_link"/>
  </joint>
  <link name="bottom_link">
    <visual>
      <origin rpy="0 0 0" xyz=" 0 0 -0.04"/>
      <geometry>
        <box size="1 1 0.02"/>
      </geometry>
      <material name="Brown"/>
    </visual>
    <collision>
      <origin rpy="0 0 0" xyz=" 0 0 -0.04"/>
      <geometry>
        <box size="1 1 0.02"/>
      </geometry>
    </collision>
    &gt;

  
  </link>
  <gazebo reference="bottom_link">
    <material>Gazebo/White</material>
  </gazebo>
  <!-- ///////////////////////////////////////////////////////////////////////////////////////////////////////////////////// -->
  <joint name="joint1" type="revolute">
    <axis xyz="0 0 1"/>
    <limit effort="3.0" lower="-2.617" upper="2.617" velocity="0.01"/>
    <origin rpy="0 0 0" xyz="0 0 0.097"/>
    <parent link="base_link"/>
    <child link="link1"/>
    <dynamics damping="50" friction="1"/>
  </joint>
  <joint name="joint2" type="revolute">
    <axis xyz="0 0 1"/>
    <limit effort="3.0" lower="-2.617" upper="2.617" velocity="0.01"/>
    <origin rpy="0 0 0" xyz="0.198 0 0"/>
    <parent link="link1"/>
    <child link="link2"/>
    <dynamics damping="50" friction="1"/>
  </joint>
  <joint name="joint3" type="prismatic">
    <axis xyz="0 0 1"/>
    <limit effort="3.0" lower="0" upper="0.1" velocity="0.01"/>
    <origin rpy="0 0 0" xyz="0.146 0 0"/>
    <parent link="link2"/>
    <child link="probe"/>
    s

    <dynamics damping="50" friction="1"/>
  </joint>
  <!-- Transmissions -->
  <!-- Transmissions for ROS Control -->
  <transmission name="tran1">
    <type>transmission_interface/SimpleTransmission</type>
    <joint name="joint1">
      <hardwareInterface>PositionJointInterface</hardwareInterface>
    </joint>
    <actuator name="motor1">
      <hardwareInterface>PositionJointInterface</hardwareInterface>
      <mechanicalReduction>1</mechanicalReduction>
    </actuator>
  </transmission>
  <transmission name="tran1">
    <type>transmission_interface/SimpleTransmission</type>
    <joint name="joint2">
      <hardwareInterface>PositionJointInterface</hardwareInterface>
    </joint>
    <actuator name="motor1">
      <hardwareInterface>PositionJointInterface</hardwareInterface>
      <mechanicalReduction>1</mechanicalReduction>
    </actuator>
  </transmission>
  <transmission name="tran1">
    <type>transmission_interface/SimpleTransmission</type>
    <joint name="joint3">
      <hardwareInterface>PositionJointInterface</hardwareInterface>
    </joint>
    <actuator name="motor1">
      <hardwareInterface>PositionJointInterface</hardwareInterface>
      <mechanicalReduction>1</mechanicalReduction>
    </actuator>
  </transmission>
  <!-- ros_control plugin -->
  <gazebo>
    <plugin filename="libgazebo_ros_control.so" name="gazebo_ros_control">
      <robotNamespace>/sr_scara_hx</robotNamespace>
    </plugin>
  </gazebo>
</robot>

