<?xml version="1.0"?>

<robot xmlns:xacro="http://www.ros.org/wiki/xacro" name="sr_scara_hx">


  <!-- Include materials -->

    <material name="Black">
        <color rgba="0.0 0.0 0.0 1.0"/>
    </material>

    <material name="Red">
        <color rgba="0.8 0.0 0.0 1.0"/>
    </material>

    <material name="White">
        <color rgba="1.0 1.0 1.0 1.0"/>
</material>

   <xacro:macro name="inertial_matrix" params="mass">
      <inertial>
      	<mass value="${mass}" />
        <inertia ixx="1.0" ixy="0.0" ixz="0.0" iyy="0.5" iyz="0.0" izz="1.0" />
      </inertial>
   </xacro:macro>

   <xacro:macro name="transmission_block" params="joint_name">
	  <transmission name="tran1">
	    <type>transmission_interface/SimpleTransmission</type>
	    <joint name="${joint_name}">
	      <hardwareInterface>PositionJointInterface</hardwareInterface>
	    </joint>
	    <actuator name="motor1">
	      <hardwareInterface>PositionJointInterface</hardwareInterface>
	      <mechanicalReduction>1</mechanicalReduction>
	    </actuator>
	  </transmission>
</xacro:macro>

<!--Links -->

<!--<xacro:property name="xyz1" value="0 0 0.097"/> -->
<!--<xacro:property name="rpy1" value="0 0 0" /> -->
<link name="base_link">
 <visual>
  <origin xyz="0 0 0.097" rpy="0 0 0" />
   <geometry>
     <mesh filename="package://robot_simulation/meshes_r01/base.stl" scale="0.001 0.001 0.001"/>  
   </geometry>
   <material name="Black">
     <color rgba="0.1 0.1 0.1 1"/>
   </material>
 </visual>
 <collision>
  <origin xyz="0 0 0.097" rpy="0 0 0" />
   <geometry>
     <mesh filename="package://robot_simulation/meshes_r01/base.stl" scale="0.001 0.001 0.001"/>  
   </geometry>
 </collision>  
<xacro:inertial_matrix mass="1"/>
</link>

 <gazebo reference="base_link">
    <material>Gazebo/White</material>
</gazebo> 

<link name="link1">
 <visual>
  <origin xyz="0 0 0" rpy="0 0 0" />
   <geometry>
     <mesh filename="package://robot_simulation/meshes_r01/link1.stl" scale="0.001 0.001 0.001"/>  
   </geometry>
   <material name="Red">
     <color rgba="0.9 0.1 0.1 1"/>
   </material>
 </visual>
 <collision>
  <origin xyz="0 0 0" rpy="0 0 0" />
   <geometry>
     <mesh filename="package://robot_simulation/meshes_r01/link1.stl" scale="0.001 0.001 0.001"/>  
   </geometry>
 </collision>
<xacro:inertial_matrix mass="1"/>
</link>

 <gazebo reference="link1">
    <material>Gazebo/Red</material>
</gazebo> 

<link name="link2">
 <visual>
  <origin xyz="-0.198 0 0" rpy="0 0 0" />
   <geometry>
     <mesh filename="package://robot_simulation/meshes_r01/link2.stl" scale="0.001 0.001 0.001"/>  
   </geometry>
   <material name="Black">
     <color rgba="0.1 0.1 0.1 1"/>
   </material>
 </visual>
 <collision>
  <origin xyz="-0.198 0 0" rpy="0 0 0" />
   <geometry>
     <mesh filename="package://robot_simulation/meshes_r01/link2.stl" scale="0.001 0.001 0.001"/>  
   </geometry>
  </collision>
	<xacro:inertial_matrix mass="1"/>
</link>

 <gazebo reference="link2">
    <material>Gazebo/Black</material>
</gazebo> 

<link name="probe">
 <visual>
  <origin xyz="-0.344 0 0" rpy="0 0 0" />
  <geometry>
     <mesh filename="package://robot_simulation/meshes_r01/probe.stl" scale="0.001 0.001 0.001"/>  
  </geometry>
  <material name="Red">
     <color rgba="0.7 0.1 0.1 1"/>
  </material>
 </visual>
 <collision>
  <origin xyz="-0.344 0 0" rpy="0 0 0" />
  <geometry>
     <mesh filename="package://robot_simulation/meshes_r01/probe.stl" scale="0.001 0.001 0.001"/>  
  </geometry>
 </collision>
<xacro:inertial_matrix mass="1"/>
</link>

 <gazebo reference="probe">
    <material>Gazebo/Red</material>
</gazebo> 


<!-- Joints -->
<!-- BOTTOM FIXED LINK 
This link is the base of the arm in which arm is placed 
-->

<!-- ///////////////////////////////////////////////////////////////////////////////////////////////////////////////////// -->

  <joint name="bottom_joint" type="fixed">
    <origin xyz="0 0 0" rpy="0 0 0" />
    <parent link="base_link"/>
    <child link="bottom_link"/>
  </joint>

  <link name="bottom_link">

    <visual>
      <origin xyz=" 0 0 -0.04"  rpy="0 0 0"/>
      <geometry>

	       <box size="1 1 0.02" />

      </geometry>
      <material name="Brown" />
    </visual>

    <collision>
      <origin xyz=" 0 0 -0.04"  rpy="0 0 0"/>
      <geometry>
	       <box size="1 1 0.02" />
      </geometry>
      </collision>>

  </link>

  <gazebo reference="bottom_link">
    <material>Gazebo/White</material>
</gazebo>

<!-- ///////////////////////////////////////////////////////////////////////////////////////////////////////////////////// -->
<joint name="joint1" type="revolute">
  <axis xyz="0 0 1" /> 
  <limit effort="3.0" velocity="0.01" lower="-2.617" upper="2.617"/>
  <origin xyz="0 0 0.097" rpy="0 0 0" />
  <parent link="base_link" />
  <child link="link1" />
<dynamics damping="50" friction="1"/>
</joint>

<joint name="joint2" type="revolute">
 <axis xyz="0 0 1" /> 
 <limit effort="3.0" velocity="0.01" lower="-2.617" upper="2.617"/>
 <origin xyz="0.198 0 0" rpy="0 0 0" />
 <parent link="link1" />
 <child link="link2" />
<dynamics damping="50" friction="1"/>
</joint>

<joint name="joint3" type="prismatic">
 <axis xyz="0 0 1" /> 
 <limit effort="3.0" velocity="0.01" lower="0" upper="0.1"/>
 <origin xyz="0.146 0 0" rpy="0 0 0" />
 <parent link="link2" />
 <child link="probe" />s
<dynamics damping="50" friction="1"/>
</joint>


<!-- Transmissions -->

  <!-- Transmissions for ROS Control -->

   <xacro:transmission_block joint_name="joint1"/>
   <xacro:transmission_block joint_name="joint2"/>
<xacro:transmission_block joint_name="joint3"/>


  <!-- ros_control plugin -->
  <gazebo>
    <plugin name="gazebo_ros_control" filename="libgazebo_ros_control.so">
      <robotNamespace>/sr_scara_hx</robotNamespace> 
    </plugin>
</gazebo>
</robot> 
